<?xml version="1.0" ?>
<robot name="david_urdf" xmlns:xacro="http://www.ros.org/wiki/xacro">

<xacro:include filename="$(find david_urdf)/urdf/materials.xacro" />
<xacro:include filename="$(find david_urdf)/urdf/david_urdf.trans" />
<xacro:include filename="$(find david_urdf)/urdf/david_urdf.gazebo" />
<link name="base_link">
  <inertial>
    <origin xyz="-0.00010607888700379353 -0.017619514249279468 0.03196567044947296" rpy="0 0 0"/>
    <mass value="0.15682103461883679"/>
    <inertia ixx="0.000591" iyy="0.000205" izz="0.000599" ixy="-0.0" iyz="3.4e-05" ixz="-0.0"/>
  </inertial>
  <visual>
    <origin xyz="0 0 0" rpy="0 0 0"/>
    <geometry>
      <mesh filename="package://david_urdf/meshes/base_link.stl" scale="0.001 0.001 0.001"/>
    </geometry>
    <material name="silver"/>
  </visual>
  <collision>
    <origin xyz="0 0 0" rpy="0 0 0"/>
    <geometry>
      <mesh filename="package://david_urdf/meshes/base_link.stl" scale="0.001 0.001 0.001"/>
    </geometry>
  </collision>
</link>

<link name="base_top_1">
  <inertial>
    <origin xyz="-5.7650948498277896e-06 -0.014245337073783216 0.01827498649570901" rpy="0 0 0"/>
    <mass value="0.12088276685744109"/>
    <inertia ixx="0.000184" iyy="7.3e-05" izz="0.000206" ixy="-0.0" iyz="-2.3e-05" ixz="-0.0"/>
  </inertial>
  <visual>
    <origin xyz="-0.0 -0.0 -0.0742" rpy="0 0 0"/>
    <geometry>
      <mesh filename="package://david_urdf/meshes/base_top_1.stl" scale="0.001 0.001 0.001"/>
    </geometry>
    <material name="silver"/>
  </visual>
  <collision>
    <origin xyz="-0.0 -0.0 -0.0742" rpy="0 0 0"/>
    <geometry>
      <mesh filename="package://david_urdf/meshes/base_top_1.stl" scale="0.001 0.001 0.001"/>
    </geometry>
  </collision>
</link>

<link name="shaft_1">
  <inertial>
    <origin xyz="0.30810499991555895 -0.18431421192725522 0.03945082608729948" rpy="0 0 0"/>
    <mass value="0.024645990884455106"/>
    <inertia ixx="1e-05" iyy="1e-05" izz="1.5e-05" ixy="-0.0" iyz="-0.0" ixz="-0.0"/>
  </inertial>
  <visual>
    <origin xyz="0.308105 -0.184366 -0.0792" rpy="0 0 0"/>
    <!-- <origin xyz="0 0 0" rpy="0 0 0"/> -->
    <geometry>
      <mesh filename="package://david_urdf/meshes/shaft_1.stl" scale="0.001 0.001 0.001"/>
    </geometry>
    <material name="silver"/>
  </visual>
  <collision>
    <origin xyz="0.308105 -0.184366 -0.0792" rpy="0 0 0"/>
    <geometry>
      <mesh filename="package://david_urdf/meshes/shaft_1.stl" scale="0.001 0.001 0.001"/>
    </geometry>
  </collision>
</link>

<link name="axis1_1">
  <inertial>
    <origin xyz="-0.004400867412475165 0.0007166252179925679 0.015564868562478934" rpy="0 0 0"/>
    <mass value="0.14468947560446446"/>
    <inertia ixx="9e-05" iyy="0.000331" izz="0.00035" ixy="3e-06" iyz="-3e-06" ixz="1.1e-05"/>
  </inertial>
  <visual>
    <origin xyz="-0.0 -0.0 -0.1262" rpy="0 0 0"/>
    <geometry>
      <mesh filename="package://david_urdf/meshes/axis1_1.stl" scale="0.001 0.001 0.001"/>
    </geometry>
    <material name="silver"/>
  </visual>
  <collision>
    <origin xyz="-0.0 -0.0 -0.1262" rpy="0 0 0"/>
    <geometry>
      <mesh filename="package://david_urdf/meshes/axis1_1.stl" scale="0.001 0.001 0.001"/>
    </geometry>
  </collision>
</link>

<link name="arm1_1">
  <inertial>
    <origin xyz="0.04046552623603067 -2.310683884249737e-06 0.054831743005482825" rpy="0 0 0"/>
    <mass value="0.13222977603489441"/>
    <inertia ixx="0.000245" iyy="0.000352" izz="0.000134" ixy="-0.0" iyz="-0.0" ixz="-4.9e-05"/>
  </inertial>
  <visual>
    <origin xyz="0.029 -0.00986 -0.16645" rpy="0 0 0"/>
    <geometry>
      <mesh filename="package://david_urdf/meshes/arm1_1.stl" scale="0.001 0.001 0.001"/>
    </geometry>
    <material name="silver"/>
  </visual>
  <collision>
    <origin xyz="0.029 -0.00986 -0.16645" rpy="0 0 0"/>
    <geometry>
      <mesh filename="package://david_urdf/meshes/arm1_1.stl" scale="0.001 0.001 0.001"/>
    </geometry>
  </collision>
</link>

<link name="arm2_1">
  <inertial>
    <origin xyz="-0.04046552623585722 2.314736902177955e-06 0.054831741127648714" rpy="0 0 0"/>
    <mass value="0.1322297760351555"/>
    <inertia ixx="0.000245" iyy="0.000352" izz="0.000134" ixy="-0.0" iyz="0.0" ixz="4.9e-05"/>
  </inertial>
  <visual>
    <origin xyz="-0.04 -0.00986 -0.27831" rpy="0 0 0"/>
    <geometry>
      <mesh filename="package://david_urdf/meshes/arm2_1.stl" scale="0.001 0.001 0.001"/>
    </geometry>
    <material name="silver"/>
  </visual>
  <collision>
    <origin xyz="-0.04 -0.00986 -0.27831" rpy="0 0 0"/>
    <geometry>
      <mesh filename="package://david_urdf/meshes/arm2_1.stl" scale="0.001 0.001 0.001"/>
    </geometry>
  </collision>
</link>

<link name="arm3_1">
  <inertial>
    <origin xyz="0.02931706315495697 -0.00020002898220798128 0.040376281001127445" rpy="0 0 0"/>
    <mass value="0.10541571710492485"/>
    <inertia ixx="0.000122" iyy="0.000209" izz="0.000118" ixy="0.0" iyz="1e-06" ixz="-1e-06"/>
  </inertial>
  <visual>
    <origin xyz="0.029 -0.00986 -0.39017" rpy="0 0 0"/>
    <geometry>
      <mesh filename="package://david_urdf/meshes/arm3_1.stl" scale="0.001 0.001 0.001"/>
    </geometry>
    <material name="silver"/>
  </visual>
  <collision>
    <origin xyz="0.029 -0.00986 -0.39017" rpy="0 0 0"/>
    <geometry>
      <mesh filename="package://david_urdf/meshes/arm3_1.stl" scale="0.001 0.001 0.001"/>
    </geometry>
  </collision>
</link>

<link name="arm4_1">
  <inertial>
    <origin xyz="0.0420399999999993 -0.015278411270449706 0.597160987598542" rpy="0 0 0"/>
    <mass value="0.016955183931064"/>
    <inertia ixx="9e-06" iyy="7e-06" izz="4e-06" ixy="0.0" iyz="3e-06" ixz="-0.0"/>
  </inertial>
  <visual>
    <origin xyz="0.04204 -0.00986 0.09" rpy="0 0 0"/>
    <geometry>
      <mesh filename="package://david_urdf/meshes/arm4_1.stl" scale="0.001 0.001 0.001"/>
    </geometry>
    <material name="silver"/>
  </visual>
  <collision>
    <origin xyz="0.04204 -0.00986 0.09" rpy="0 0 0"/>
    <geometry>
      <mesh filename="package://david_urdf/meshes/arm4_1.stl" scale="0.001 0.001 0.001"/>
    </geometry>
  </collision>
</link>

<joint name="Rigid 1" type="fixed">
  <origin xyz="0.0 0.0 0.0742" rpy="0 0 0"/>
  <parent link="base_link"/>
  <child link="base_top_1"/>
</joint>

<joint name="Revolute 2" type="continuous">
  <!-- <origin xyz="-0.308105 0.184366 0.005" rpy="0 0 0"/> -->
  <origin xyz="0 0 0" rpy="0 0 0"/>  <!-- try simpler -->
  <parent link="base_top_1"/>
  <child link="shaft_1"/>
  <axis xyz="-0.0 0.0 -1.0"/>

</joint>

<joint name="Rigid 3" type="fixed">
  <origin xyz="0.308105 -0.184366 0.047" rpy="0 0 0"/>
  <parent link="shaft_1"/>
  <child link="axis1_1"/>
</joint>

<joint name="Revolute 4" type="continuous">
  <origin xyz="-0.029 0.00986 0.04025" rpy="0 0 0"/>
  <parent link="axis1_1"/>
  <child link="arm1_1"/>
  <axis xyz="1.0 0.0 0.0"/>
</joint>

<joint name="Revolute 5" type="continuous">
  <origin xyz="0.069 0.0 0.11186" rpy="0 0 0"/>
  <parent link="arm1_1"/>
  <child link="arm2_1"/>
  <axis xyz="-1.0 -0.0 -0.0"/>
</joint>

<joint name="Revolute 6" type="continuous">
  <origin xyz="-0.069 0.0 0.11186" rpy="0 0 0"/>
  <parent link="arm2_1"/>
  <child link="arm3_1"/>
  <axis xyz="1.0 0.0 0.0"/>
</joint>

<joint name="Revolute 8" type="continuous">
  <origin xyz="-0.01304 0.0 -0.48017" rpy="0 0 0"/>
  <parent link="arm3_1"/>
  <child link="arm4_1"/>
  <axis xyz="-0.0 -0.0 1.0"/>
</joint>

</robot>
